<?xml version="1.0"?>
<!--

Copyright (c) 2020, Botsync Pte. Ltd.
All rights reserved.

Redistribution and use in source and binary forms, with or without
modification, are permitted provided that the following conditions are met:
    * Redistributions of source code must retain the above copyright
      notice, this list of conditions and the following disclaimer.
    * Redistributions in binary form must reproduce the above copyright
      notice, this list of conditions and the following disclaimer in the
      documentation and/or other materials provided with the distribution.
    * Neither the name of the Botsync Pte. Ltd. nor the
      names of its contributors may be used to endorse or promote products
      derived from this software without specific prior written permission.

THIS SOFTWARE IS PROVIDED BY THE COPYRIGHT HOLDERS AND CONTRIBUTORS "AS IS" AND
ANY EXPRESS OR IMPLIED WARRANTIES, INCLUDING, BUT NOT LIMITED TO, THE IMPLIED
WARRANTIES OF MERCHANTABILITY AND FITNESS FOR A PARTICULAR PURPOSE ARE
DISCLAIMED. IN NO EVENT SHALL <COPYRIGHT HOLDER> BE LIABLE FOR ANY
DIRECT, INDIRECT, INCIDENTAL, SPECIAL, EXEMPLARY, OR CONSEQUENTIAL DAMAGES
(INCLUDING, BUT NOT LIMITED TO, PROCUREMENT OF SUBSTITUTE GOODS OR SERVICES;
LOSS OF USE, DATA, OR PROFITS; OR BUSINESS INTERRUPTION) HOWEVER CAUSED AND
ON ANY THEORY OF LIABILITY, WHETHER IN CONTRACT, STRICT LIABILITY, OR TORT
(INCLUDING NEGLIGENCE OR OTHERWISE) ARISING IN ANY WAY OUT OF THE USE OF THIS
SOFTWARE, EVEN IF ADVISED OF THE POSSIBILITY OF SUCH DAMAGE.

-->

<robot name="volta_robot" xmlns:xacro="https://ros.org/wiki/xacro">
    <!-- Wheel Macro -->
    <xacro:macro name="volta_wheel" params="wheel_prefix *joint_origin">

        <!-- Wheel Link -->
        <link name="${wheel_prefix}_wheel">
            <visual>
                <origin xyz="0 0 0" rpy="1.570796327 0 0"/>
                <geometry>
                    <cylinder length="${wheel_width}" radius="${wheel_radius}"/>
                </geometry>
                <material name="red"/>
            </visual>
            <collision>
                <origin xyz="0 0 0" rpy="1.570796327 0 0"/>
                <geometry>
                    <cylinder length="${wheel_width}" radius="${wheel_radius}" />
                </geometry>
            </collision>
            <inertial>
                <mass value="${wheel_mass}" />
                <origin xyz="0 0 0" rpy="0 0 0" />
                <inertia  ixx="${wheel_ixx}" ixy="${wheel_ixy}" ixz="${wheel_ixz}" iyy="${wheel_iyy}" iyz="${wheel_iyz}" izz="${wheel_izz}" />
            </inertial>
        </link>

        <gazebo reference="${wheel_prefix}_wheel">
            <material>Gazebo/Red</material>
            <mu1 value="1400"/>
            <mu2 value="600"/>
            <kp value="3100000.0"></kp>
            <kd value="1.0"></kd>
            <fdir1 value="1 0 0"/>
        </gazebo>

        <!-- Wheel Joint -->
        <joint name="${wheel_prefix}_wheel_joint" type="continuous">
            <parent link="base_link"/>
            <child link="${wheel_prefix}_wheel" />
            <xacro:insert_block name="joint_origin" />
            <axis xyz="0 1 0" />
        </joint>

        <!-- Wheel Transmission -->
        <transmission name="${wheel_prefix}_wheel_transmission" type="SimpleTransmission">
            <type>transmission_interface/SimpleTransmission</type>
            <joint name="${wheel_prefix}_wheel_joint">
                <hardwareInterface>hardware_interface/VelocityJointInterface</hardwareInterface>
            </joint>
            <actuator name="${wheel_prefix}_motor">
                <mechanicalReduction>1</mechanicalReduction>
            </actuator>
        </transmission>
    </xacro:macro>
</robot>
